INFO:app:Initializing Flask application
[2025-04-20 11:21:18 +0000] [390181] [ERROR] Exception in worker process
Traceback (most recent call last):
  File "/home/clau/productiva/venv/lib/python3.12/site-packages/gunicorn/arbiter.py", line 608, in spawn_worker
    worker.init_process()
  File "/home/clau/productiva/venv/lib/python3.12/site-packages/gunicorn/workers/base.py", line 135, in init_process
    self.load_wsgi()
  File "/home/clau/productiva/venv/lib/python3.12/site-packages/gunicorn/workers/base.py", line 147, in load_wsgi
    self.wsgi = self.app.wsgi()
                ^^^^^^^^^^^^^^^
  File "/home/clau/productiva/venv/lib/python3.12/site-packages/gunicorn/app/base.py", line 66, in wsgi
    self.callable = self.load()
                    ^^^^^^^^^^^
  File "/home/clau/productiva/venv/lib/python3.12/site-packages/gunicorn/app/wsgiapp.py", line 57, in load
    return self.load_wsgiapp()
           ^^^^^^^^^^^^^^^^^^^
  File "/home/clau/productiva/venv/lib/python3.12/site-packages/gunicorn/app/wsgiapp.py", line 47, in load_wsgiapp
    return util.import_app(self.app_uri)
           ^^^^^^^^^^^^^^^^^^^^^^^^^^^^^
  File "/home/clau/productiva/venv/lib/python3.12/site-packages/gunicorn/util.py", line 370, in import_app
    mod = importlib.import_module(module)
          ^^^^^^^^^^^^^^^^^^^^^^^^^^^^^^^
  File "/usr/lib/python3.12/importlib/__init__.py", line 90, in import_module
    return _bootstrap._gcd_import(name[level:], package, level)
           ^^^^^^^^^^^^^^^^^^^^^^^^^^^^^^^^^^^^^^^^^^^^^^^^^^^^
  File "<frozen importlib._bootstrap>", line 1387, in _gcd_import
  File "<frozen importlib._bootstrap>", line 1360, in _find_and_load
  File "<frozen importlib._bootstrap>", line 1331, in _find_and_load_unlocked
  File "<frozen importlib._bootstrap>", line 935, in _load_unlocked
  File "<frozen importlib._bootstrap_external>", line 995, in exec_module
  File "<frozen importlib._bootstrap>", line 488, in _call_with_frames_removed
  File "/home/clau/productiva/app.py", line 185, in <module>
    app = create_app()
          ^^^^^^^^^^^^
  File "/home/clau/productiva/app.py", line 62, in create_app
    from routes import (auth_bp, main_bp, company_bp, employee_bp, user_bp,
  File "/home/clau/productiva/routes.py", line 16, in <module>
    from models_checkpoints import CheckPoint
  File "/home/clau/productiva/models_checkpoints.py", line 7, in <module>
    from models import Employee, Company, Base
ImportError: cannot import name 'Base' from 'models' (/home/clau/productiva/models.py)