(venv) clau@clauelx:~/productiva$ gunicorn app:app -b 0.0.0.0:5001
[2025-04-19 21:03:59 +0000] [250627] [INFO] Starting gunicorn 23.0.0
[2025-04-19 21:03:59 +0000] [250627] [INFO] Listening at: http://0.0.0.0:5001 (250627)
[2025-04-19 21:03:59 +0000] [250627] [INFO] Using worker: sync
[2025-04-19 21:03:59 +0000] [250628] [INFO] Booting worker with pid: 250628
INFO:app:Initializing Flask application
[2025-04-19 21:03:59 +0000] [250628] [ERROR] Exception in worker process
Traceback (most recent call last):
  File "/home/clau/productiva/venv/lib/python3.12/site-packages/gunicorn/arbiter.py", line 608, in spawn_worker
    worker.init_process()
  File "/home/clau/productiva/venv/lib/python3.12/site-packages/gunicorn/workers/base.py", line 135, in init_process
    self.load_wsgi()
  File "/home/clau/productiva/venv/lib/python3.12/site-packages/gunicorn/workers/base.py", line 147, in load_wsgi
    self.wsgi = self.app.wsgi()
                ^^^^^^^^^^^^^^^
  File "/home/clau/productiva/venv/lib/python3.12/site-packages/gunicorn/app/base.py", line 66, in wsgi
    self.callable = self.load()
                    ^^^^^^^^^^^
  File "/home/clau/productiva/venv/lib/python3.12/site-packages/gunicorn/app/wsgiapp.py", line 57, in load
    return self.load_wsgiapp()
           ^^^^^^^^^^^^^^^^^^^
  File "/home/clau/productiva/venv/lib/python3.12/site-packages/gunicorn/app/wsgiapp.py", line 47, in load_wsgiapp
    return util.import_app(self.app_uri)
           ^^^^^^^^^^^^^^^^^^^^^^^^^^^^^
  File "/home/clau/productiva/venv/lib/python3.12/site-packages/gunicorn/util.py", line 370, in import_app
    mod = importlib.import_module(module)
          ^^^^^^^^^^^^^^^^^^^^^^^^^^^^^^^
  File "/usr/lib/python3.12/importlib/__init__.py", line 90, in import_module
    return _bootstrap._gcd_import(name[level:], package, level)
           ^^^^^^^^^^^^^^^^^^^^^^^^^^^^^^^^^^^^^^^^^^^^^^^^^^^^
  File "<frozen importlib._bootstrap>", line 1387, in _gcd_import
  File "<frozen importlib._bootstrap>", line 1360, in _find_and_load
  File "<frozen importlib._bootstrap>", line 1331, in _find_and_load_unlocked
  File "<frozen importlib._bootstrap>", line 935, in _load_unlocked
  File "<frozen importlib._bootstrap_external>", line 995, in exec_module
  File "<frozen importlib._bootstrap>", line 488, in _call_with_frames_removed
  File "/home/clau/productiva/app.py", line 174, in <module>
    app = create_app()
          ^^^^^^^^^^^^
  File "/home/clau/productiva/app.py", line 35, in create_app
    app.config.from_object(config_class)
  File "/home/clau/productiva/venv/lib/python3.12/site-packages/flask/config.py", line 251, in from_object
    obj = import_string(obj)
          ^^^^^^^^^^^^^^^^^^
  File "/home/clau/productiva/venv/lib/python3.12/site-packages/werkzeug/utils.py", line 612, in import_string
    raise ImportStringError(import_name, e).with_traceback(
  File "/home/clau/productiva/venv/lib/python3.12/site-packages/werkzeug/utils.py", line 604, in import_string
    module = __import__(module_name, globals(), locals(), [obj_name])
             ^^^^^^^^^^^^^^^^^^^^^^^^^^^^^^^^^^^^^^^^^^^^^^^^^^^^^^^^
werkzeug.utils.ImportStringError: import_string() failed for 'config.Config'. Possible reasons are:

- missing __init__.py in a package;
- package or module path not included in sys.path;
- duplicated package or module name taking precedence in sys.path;
- missing module, class, function or variable;

Debugged import:

- 'config' not found.

Original exception:

ModuleNotFoundError: No module named 'config'
[2025-04-19 21:03:59 +0000] [250628] [INFO] Worker exiting (pid: 250628)
[2025-04-19 21:03:59 +0000] [250627] [ERROR] Worker (pid:250628) exited with code 3
[2025-04-19 21:03:59 +0000] [250627] [ERROR] Shutting down: Master
[2025-04-19 21:03:59 +0000] [250627] [ERROR] Reason: Worker failed to boot.