(venv) clau@clauelx:~/productiva$ flask db upgrade
INFO:app:Initializing Flask application
ERROR:checkpoint_closer_service:No se pudo iniciar el servicio de cierre automático
WARNING:app:⚠ No se pudo iniciar el servicio de cierre automático
INFO  [alembic.runtime.migration] Context impl PostgresqlImpl.
INFO  [alembic.runtime.migration] Will assume transactional DDL.
INFO  [alembic.runtime.migration] Running upgrade  -> 6a9d8f1a6e1d, Add bank_account column to companies and adjust phone length
Traceback (most recent call last):
  File "/home/clau/productiva/venv/lib/python3.12/site-packages/sqlalchemy/engine/base.py", line 1964, in _exec_single_context
    self.dialect.do_execute(
  File "/home/clau/productiva/venv/lib/python3.12/site-packages/sqlalchemy/engine/default.py", line 942, in do_execute
    cursor.execute(statement, parameters)
psycopg2.errors.DuplicateColumn: column "bank_account" of relation "companies" already exists


The above exception was the direct cause of the following exception:

****************************************************************************************************

* INICIANDO FUNCIÓN DE BARRIDO AUTOMÁTICO
* Fecha/hora: 2025-04-20 13:38:10.785382
* Versión: 1.2.0
* Primer inicio después de redeploy: No
Traceback (most recent call last):
  File "/home/clau/productiva/venv/bin/flask", line 8, in <module>
****************************************************************************************************

========== INICIO BARRIDO DE CIERRE AUTOMÁTICO: 2025-04-20 13:38:10.785382 ==========
Ejecutando verificación de cierre automático dentro de la ventana horaria configurada: 2025-04-20 13:38:10.785382
Hora actual (Madrid): 15:38:10.785537
    sys.exit(main())
             ^^^^^^
  File "/home/clau/productiva/venv/lib/python3.12/site-packages/flask/cli.py", line 1129, in main
    cli.main()
  File "/home/clau/productiva/venv/lib/python3.12/site-packages/click/core.py", line 1082, in main
    rv = self.invoke(ctx)
         ^^^^^^^^^^^^^^^^
  File "/home/clau/productiva/venv/lib/python3.12/site-packages/click/core.py", line 1697, in invoke
    return _process_result(sub_ctx.command.invoke(sub_ctx))

========== ERROR EN BARRIDO DE CIERRE AUTOMÁTICO ==========
Fecha y hora de inicio: 2025-04-20 13:38:10.785382
Fecha y hora de error: 2025-04-20 13:38:10.788664
Primer inicio tras redeploy: No
Error general durante el proceso: (psycopg2.errors.InvalidTextRepresentation) invalid input value for enum checkpoint_status: "ACTIVE"
LINE 3: ...ation_end_time IS NOT NULL AND checkpoints.status = 'ACTIVE'
                                                               ^

[SQL: SELECT checkpoints.id AS checkpoints_id, checkpoints.name AS checkpoints_name, checkpoints.description AS checkpoints_description, checkpoints.location AS checkpoints_location, checkpoints.status AS checkpoints_status, checkpoints.username AS checkpoints_username, checkpoints.password_hash AS checkpoints_password_hash, checkpoints.created_at AS checkpoints_created_at, checkpoints.updated_at AS checkpoints_updated_at, checkpoints.company_id AS checkpoints_company_id, checkpoints.enforce_contract_hours AS checkpoints_enforce_contract_hours, checkpoints.auto_adjust_overtime AS checkpoints_auto_adjust_overtime, checkpoints.operation_start_time AS checkpoints_operation_start_time, checkpoints.operation_end_time AS checkpoints_operation_end_time, checkpoints.enforce_operation_hours AS checkpoints_enforce_operation_hours 
FROM checkpoints 
WHERE checkpoints.enforce_operation_hours = true AND checkpoints.operation_start_time IS NOT NULL AND checkpoints.operation_end_time IS NOT NULL AND checkpoints.status = %(status_1)s]
[parameters: {'status_1': 'ACTIVE'}]
(Background on this error at: https://sqlalche.me/e/20/9h9h)
========== FIN BARRIDO CON ERROR ==========

                           ^^^^^^^^^^^^^^^^^^^^^^^^^^^^^^^
  File "/home/clau/productiva/venv/lib/python3.12/site-packages/click/core.py", line 1697, in invoke
    return _process_result(sub_ctx.command.invoke(sub_ctx))
                           ^^^^^^^^^^^^^^^^^^^^^^^^^^^^^^^
  File "/home/clau/productiva/venv/lib/python3.12/site-packages/click/core.py", line 1443, in invoke
    return ctx.invoke(self.callback, **ctx.params)
           ^^^^^^^^^^^^^^^^^^^^^^^^^^^^^^^^^^^^^^^
  File "/home/clau/productiva/venv/lib/python3.12/site-packages/click/core.py", line 788, in invoke
    return __callback(*args, **kwargs)
           ^^^^^^^^^^^^^^^^^^^^^^^^^^^
  File "/home/clau/productiva/venv/lib/python3.12/site-packages/click/decorators.py", line 33, in new_func
    return f(get_current_context(), *args, **kwargs)
           ^^^^^^^^^^^^^^^^^^^^^^^^^^^^^^^^^^^^^^^^^
  File "/home/clau/productiva/venv/lib/python3.12/site-packages/flask/cli.py", line 400, in decorator
    return ctx.invoke(f, *args, **kwargs)
           ^^^^^^^^^^^^^^^^^^^^^^^^^^^^^^
  File "/home/clau/productiva/venv/lib/python3.12/site-packages/click/core.py", line 788, in invoke
    return __callback(*args, **kwargs)
           ^^^^^^^^^^^^^^^^^^^^^^^^^^^
  File "/home/clau/productiva/venv/lib/python3.12/site-packages/flask_migrate/cli.py", line 157, in upgrade
    _upgrade(directory or g.directory, revision, sql, tag, x_arg or g.x_arg)
  File "/home/clau/productiva/venv/lib/python3.12/site-packages/flask_migrate/__init__.py", line 111, in wrapped
    f(*args, **kwargs)
  File "/home/clau/productiva/venv/lib/python3.12/site-packages/flask_migrate/__init__.py", line 200, in upgrade
    command.upgrade(config, revision, sql=sql, tag=tag)
  File "/home/clau/productiva/venv/lib/python3.12/site-packages/alembic/command.py", line 408, in upgrade
    script.run_env()
  File "/home/clau/productiva/venv/lib/python3.12/site-packages/alembic/script/base.py", line 586, in run_env
    util.load_python_file(self.dir, "env.py")
  File "/home/clau/productiva/venv/lib/python3.12/site-packages/alembic/util/pyfiles.py", line 95, in load_python_file
    module = load_module_py(module_id, path)
             ^^^^^^^^^^^^^^^^^^^^^^^^^^^^^^^
  File "/home/clau/productiva/venv/lib/python3.12/site-packages/alembic/util/pyfiles.py", line 113, in load_module_py
    spec.loader.exec_module(module)  # type: ignore
    ^^^^^^^^^^^^^^^^^^^^^^^^^^^^^^^
  File "<frozen importlib._bootstrap_external>", line 995, in exec_module
  File "<frozen importlib._bootstrap>", line 488, in _call_with_frames_removed
  File "/home/clau/productiva/migrations/env.py", line 113, in <module>
    run_migrations_online()
  File "/home/clau/productiva/migrations/env.py", line 107, in run_migrations_online
    context.run_migrations()
  File "<string>", line 8, in run_migrations
  File "/home/clau/productiva/venv/lib/python3.12/site-packages/alembic/runtime/environment.py", line 946, in run_migrations
    self.get_context().run_migrations(**kw)
  File "/home/clau/productiva/venv/lib/python3.12/site-packages/alembic/runtime/migration.py", line 623, in run_migrations
    step.migration_fn(**kw)
  File "/home/clau/productiva/migrations/versions/add_bank_account_to_companies.py", line 21, in upgrade
    op.add_column('companies', sa.Column('bank_account', sa.String(24), nullable=True))
  File "<string>", line 8, in add_column
  File "<string>", line 3, in add_column
  File "/home/clau/productiva/venv/lib/python3.12/site-packages/alembic/operations/ops.py", line 2157, in add_column
    return operations.invoke(op)
           ^^^^^^^^^^^^^^^^^^^^^
  File "/home/clau/productiva/venv/lib/python3.12/site-packages/alembic/operations/base.py", line 441, in invoke
    return fn(self, operation)
           ^^^^^^^^^^^^^^^^^^^
  File "/home/clau/productiva/venv/lib/python3.12/site-packages/alembic/operations/toimpl.py", line 170, in add_column
    operations.impl.add_column(table_name, column, schema=schema, **kw)
  File "/home/clau/productiva/venv/lib/python3.12/site-packages/alembic/ddl/impl.py", line 373, in add_column
    self._exec(base.AddColumn(table_name, column, schema=schema))
  File "/home/clau/productiva/venv/lib/python3.12/site-packages/alembic/ddl/impl.py", line 246, in _exec
    return conn.execute(construct, params)
           ^^^^^^^^^^^^^^^^^^^^^^^^^^^^^^^
  File "/home/clau/productiva/venv/lib/python3.12/site-packages/sqlalchemy/engine/base.py", line 1416, in execute
    return meth(
           ^^^^^
  File "/home/clau/productiva/venv/lib/python3.12/site-packages/sqlalchemy/sql/ddl.py", line 180, in _execute_on_connection
    return connection._execute_ddl(
           ^^^^^^^^^^^^^^^^^^^^^^^^
  File "/home/clau/productiva/venv/lib/python3.12/site-packages/sqlalchemy/engine/base.py", line 1527, in _execute_ddl
    ret = self._execute_context(
          ^^^^^^^^^^^^^^^^^^^^^^
  File "/home/clau/productiva/venv/lib/python3.12/site-packages/sqlalchemy/engine/base.py", line 1843, in _execute_context
    return self._exec_single_context(
           ^^^^^^^^^^^^^^^^^^^^^^^^^^
  File "/home/clau/productiva/venv/lib/python3.12/site-packages/sqlalchemy/engine/base.py", line 1983, in _exec_single_context
    self._handle_dbapi_exception(
  File "/home/clau/productiva/venv/lib/python3.12/site-packages/sqlalchemy/engine/base.py", line 2352, in _handle_dbapi_exception
    raise sqlalchemy_exception.with_traceback(exc_info[2]) from e
  File "/home/clau/productiva/venv/lib/python3.12/site-packages/sqlalchemy/engine/base.py", line 1964, in _exec_single_context
    self.dialect.do_execute(
  File "/home/clau/productiva/venv/lib/python3.12/site-packages/sqlalchemy/engine/default.py", line 942, in do_execute
    cursor.execute(statement, parameters)
sqlalchemy.exc.ProgrammingError: (psycopg2.errors.DuplicateColumn) column "bank_account" of relation "companies" already exists

[SQL: ALTER TABLE companies ADD COLUMN bank_account VARCHAR(24)]
(Background on this error at: https://sqlalche.me/e/20/f405)
(venv) clau@clauelx:~/productiva$ 
